<!DOCTYPE html>
<html lang="en">

<head>
    <meta charset="UTF-8">
    <meta name="viewport" content="width=device-width, initial-scale=1.0">
    <title>Document</title>
</head>

<body>

    <!-- <script>
        const promise = new Promise((resolve, reject) => {
             console.log("hello")// Perform the asynchronous operation here
            if (success) {
                resolve(value);
            } else {
                reject(error);
            }
        });

        promise.then(value => {
            // Handle the successful result here
        }).catch(error => {
            // Handle the error here
        });
    </script> -->


    <!-- <script>

        const myFirstPromise = new Promise((resolve, reject) => {
            // We call resolve(...) when what we were doing asynchronously was successful, and reject(...) when it failed.
            // In this example, we use setTimeout(...) to simulate async code.
            // In reality, you will probably be using something like XHR or an HTML API.
            setTimeout(() => {
                resolve("Success!"); // Yay! Everything went well!
            }, 2500);
        });

        myFirstPromise.then((successMessage) => {
            // successMessage is whatever we passed in the resolve(...) function above.
            // It doesn't have to be a string, but if it is only a succeed message, it probably will be.
            console.log(`Yay! ${successMessage}`);
        });

    </script> -->


    <script>

        // To experiment with error handling, "threshold" values cause errors randomly
const THRESHOLD_A = 8; // can use zero 0 to guarantee error

function tetheredGetNumber(resolve, reject) {
  setTimeout(() => {
    const randomInt = Date.now();
    const value = randomInt % 10;
    if (value < THRESHOLD_A) {
      resolve(value);
    } else {
      reject(`Too large: ${value}`);
    }
  }, 500);
}

function determineParity(value) {
  const isOdd = value % 2 === 1;
  return { value, isOdd };
}

function troubleWithGetNumber(reason) {
  const err = new Error("Trouble getting number", { cause: reason });
  console.error(err);
  throw err;
}

function promiseGetWord(parityInfo) {
  return new Promise((resolve, reject) => {
    const { value, isOdd } = parityInfo;
    if (value >= THRESHOLD_A - 1) {
      reject(`Still too large: ${value}`);
    } else {
      parityInfo.wordEvenOdd = isOdd ? "odd" : "even";
      resolve(parityInfo);
    }
  });
}

new Promise(tetheredGetNumber)
  .then(determineParity, troubleWithGetNumber)
  .then(promiseGetWord)
  .then((info) => {
    console.log(`Got: ${info.value}, ${info.wordEvenOdd}`);
    return info;
  })
  .catch((reason) => {
    if (reason.cause) {
      console.error("Had previously handled error");
    } else {
      console.error(`Trouble with promiseGetWord(): ${reason}`);
    }
  })
  .finally((info) => console.log("All done"));

    </script>
</body>

</html>